<!-- ======================================================
	
	Model 		: UR5 Arm	
	Author		: Karthikeyan Jaganathan
	Institute       : Institute for Artificial Intelligence, University of Bremen.
	Contacts 	: ka_ja@uni-bremen.de	
	Last edits 	: 03.12.2016,20.12.2016,25.01.2017

====================================================== -->

<mujoco model="UR5">

  <compiler coordinate="local" 
	    meshdir="meshes/"
	    inertiafromgeom="false"	    
	    balanceinertia="true" 
	    boundinertia="0.00001" 
	    boundmass="0.001"
	    angle="radian"
	    eulerseq ="xyz"/>

  <option   timestep="0.01" iterations='20'
	    gravity="0 0 0" viscosity="0"/>

  <default>
    <joint damping="1" limited="true"/>
    <default class="0">
	<mesh scale = "1 1 1"/>
    </default>
    <default class="1">
	<mesh scale = "0.001 0.001 0.001"/>
    </default>

  	<!-- Barrett -->
    <default class="wam/bhand">
			<joint type="hinge" limited="true" pos="0 0 0" axis="0 0 1" frictional="true" frictionloss=".001"/>
			<geom type="mesh" contype="0" conaffinity="1" group="0" rgba="0.5 0.6 0.7 1"/>			
		</default>
		<default class="wam/bhandViz">
			<geom type="mesh" contype="0" conaffinity="0" group="1" rgba="0.7 0.8 0.8 1"/>
		</default>
  </default>
  
  <asset>
	<mesh file="base.stl"/>
	<mesh file="shoulder.stl"/>
	<mesh file="upper_arm.stl"/>
	<mesh file="forearm.stl"/>
	<mesh file="wrist_1.stl"/>
	<mesh file="wrist_2.stl"/>
	<mesh file="wrist_3.stl"/>

	<material name="GndMat" specular=".3" shininess=".3" reflectance="0.3" rgba="0.5 0.5 0.8  1"/>
	<material name="RobMat" specular=".3" shininess=".5" reflectance="0.5" rgba="0.7 0.7 0.7  1"/>
	<material name="GriMat" specular=".3" shininess=".5" reflectance="0.5" rgba="0.8 0.4 0.4  1"/>
	<material name="FinMat" specular=".3" shininess=".5" reflectance="0.5" rgba="0.1 0.1 0.1  1"/>
  	
  	<!-- Barrett -->
  	<mesh file="bhand_palm_fine.stl"/>
		<mesh file="bhand_palm_link_convex_decomposition_p1.stl"/>
		<mesh file="bhand_palm_link_convex_decomposition_p2.stl"/>
		<mesh file="bhand_palm_link_convex_decomposition_p3.stl"/>
		<mesh file="bhand_palm_link_convex_decomposition_p4.stl"/>
		<mesh file="bhand_finger_prox_link_fine.stl"/>
		<mesh file="bhand_finger_prox_link_convex_decomposition_p1.stl"/>
		<mesh file="bhand_finger_prox_link_convex_decomposition_p2.stl"/>
		<mesh file="bhand_finger_prox_link_convex_decomposition_p3.stl"/>
		<mesh file="bhand_finger_med_link_fine.stl"/>
		<mesh file="bhand_finger_med_link_convex.stl"/>
		<mesh file="bhand_finger_dist_link_fine.stl"/>
		<mesh file="bhand_finger_dist_link_convex.stl"/>
  </asset>
  
  
  <worldbody>
	<light directional="true" cutoff="4" exponent="20" diffuse="1 1 1" specular="0 0 0" pos=".5 0.75 1.5" dir="-.5 -0.75 -1.5"/>
	<geom name="gnd" material="GndMat" type="plane" contype="1" conaffinity="1" pos="0 0 0" size="1.5 0.75 0.001"/>

      	<body name="base_link" euler="0 0 3.14" pos="0 0 0">
	      	<inertial pos="0 0 0" euler="0 0 0" mass="4.0" 
			  diaginertia="0.00443333156 0.00443333156 0.0072" />
	      	<geom name="base_g" material="RobMat"  type="mesh" mesh="base"/>
	
	<body name="shoulder_link" euler="0 0 0" pos="0 0 0.089159">
	      	<inertial pos="0 0 0" euler="0 0 0" mass="3.7" 
			  diaginertia="0.010267495893 0.010267495893 0.0072" />
	      	<geom name="shoulder_g" material="RobMat"  type="mesh" mesh="shoulder"/>
		<joint  name="shoulder_pan_joint" type="hinge" axis="0 0 1" limited="true" frictional="true"
			range="-3.14159265 3.14159265" 			
			damping="10.0" frictionloss="0"/>
	
	<body name="upper_arm_link" euler="0 1.570796325 0" pos="0 0.13585 0">
	      	<inertial euler="0 0 0"  pos="0 0 0.28" mass="8.393"
			  diaginertia="0.22689067591 0.22689067591 0.0151074" />
	      	<geom name="upper_arm_g" material="RobMat"  type="mesh" mesh="upper_arm"/>
		<joint  name="shoulder_lift_joint" type="hinge" axis="0 1 0" limited="true" frictional="true"
			range="-3.14159265 3.14159265" 			
			damping="10.0" frictionloss="0"/>
	
	<body name="forearm_link" euler="0 0 0" pos="0 -0.1197 0.425">
	      	<inertial euler="0 0 0"  pos="0 0 0.25" mass="2.275"
			  diaginertia="0.049443313556 0.049443313556 0.004095" />
	      	<geom name="forearm_g" material="RobMat"  type="mesh" mesh="forearm"/>
		<joint  name="elbow_joint" type="hinge" axis="0 1 0" limited="true" frictional="true"
			range="-3.14159265 3.14159265" 			
			damping="10.0" frictionloss="0"/>

	<body name="wrist_1_link" euler="0 1.570796325 0" pos="0 0 0.39225">
	      	<inertial euler="0 0 0"  pos="0 0 0" mass="1.219"
			  diaginertia="0.111172755531 0.111172755531 0.21942" />
	      	<geom name="wrist1_g" material="RobMat"  type="mesh" mesh="wrist_1"/>
		<joint  name="wrist_1_joint" type="hinge" axis="0 1 0" limited="true" frictional="true"
			range="-3.14159265 3.14159265" 			
			damping="10.0" frictionloss="0"/>

	<body name="wrist_2_link" euler="0 0 0" pos="0 0.093 0">
	      	<inertial euler="0 0 0"  pos="0 0 0" mass="1.219"
			  diaginertia="0.111172755531 0.111172755531 0.21942" />
	      	<geom name="wrist2_g" material="RobMat"  type="mesh" mesh="wrist_2"/>
		<joint  name="wrist_2_joint" type="hinge" axis="0 0 1" limited="true" frictional="true"
			range="-3.14159265 3.14159265" 			
			damping="10.0" frictionloss="0"/>

	<body name="wrist_3_link" euler="0 0 0" pos="0 0 0.09465">
	      	<inertial euler="0 0 0"  pos="0 0 0" mass="0.1879"
			  diaginertia="0.0171364731454 0.0171364731454 0.033822" />
	      	<geom name="wrist3_g" material="RobMat"  type="mesh" mesh="wrist_3"/>
		<joint  name="wrist_3_joint" type="hinge" axis="0 1 0" limited="true" frictional="true"
			range="-3.14159265 3.14159265" 			
			damping="10.0" frictionloss="0"/>
	
	<body name="ee_link" euler="-1.570796325 0 0" pos="0 0.0823 0">
      		<geom name="ee_link_g" material="RobMat" rgba="0.1 0.1 0.9 1" type="box" size="0.01 0.01 0.01"/>

<!-- 	<include file = "gripper.xml"/>
 --> 
	</body>
	</body>
	</body>
	</body>
	</body>
	</body>
	</body>
	</body>

	<!-- Target -->
		<body name="target" pos="0 0 0">
			<joint axis="1 0 0" name="target_x" type="slide" range="-2 2"/>
			<joint axis="0 1 0" name="target_y" type="slide" range="-2 2"/>
			<joint axis="0 0 1" name="target_z" type="slide" range="-2 2"/>
			<!-- <joint armature="0" axis="1 0 0" damping="0" limited="true" name="target_x" pos="0 0 0" range="-.27 .27" ref=".1" stiffness="0" type="slide"/>
			<joint armature="0" axis="0 1 0" damping="0" limited="true" name="target_y" pos="0 0 0" range="-.27 .27" ref="-.1" stiffness="0" type="slide"/> -->
			<geom conaffinity="0" contype="0" name="target" pos="0 0 0" rgba="0.9 0.2 0.2 1" size=".03" type="sphere"/>
		</body>
  </worldbody>

  <actuator>
<!-- 	<motor name="shoulder_pan_torque" joint="shoulder_pan_joint" ctrllimited="true" ctrlrange="-1.0 1.0" gear="200.0"/>
	<motor name="shoulder_lift_torque" joint="shoulder_lift_joint" ctrllimited="true" ctrlrange="-1.0 1.0" gear="200.0"/>
	<motor name="elbow_torque" joint="elbow_joint" ctrllimited="true" ctrlrange="-1.0 1.0" gear="200.0"/>
	<motor name="wrist_1_torque" joint="wrist_1_joint" ctrllimited="true" ctrlrange="-1.0 1.0" gear="200.0"/>
	<motor name="wrist_2_torque" joint="wrist_2_joint" ctrllimited="true" ctrlrange="-1.0 1.0" gear="200.0"/>
	<motor name="wrist_3_torque" joint="wrist_3_joint" ctrllimited="true" ctrlrange="-1.0 1.0" gear="200.0"/> -->
<!-- 	<motor name="left_finger_torque" joint="gripper_base_left_finger_joint" ctrllimited="true" ctrlrange="-1.0 1.0" gear="200.0"/>
	<motor name="right_finger_torque" joint="gripper_base_right_finger_joint" ctrllimited="true" ctrlrange="-1.0 1.0" gear="200.0"/> -->

	<position name="shoulder_pan_act" joint="shoulder_pan_joint" kp="10" ctrlrange="-3.14159265 3.14159265" ctrllimited="true"/>
	<position name="shoulder_lift_act" joint="shoulder_lift_joint" kp="100" ctrlrange="-3.14159265 3.14159265" ctrllimited="true"/>
	<position name="elbow_act" joint="elbow_joint" kp="100" ctrlrange="-3.14159265 3.14159265" ctrllimited="true"/>
	<position name="wrist_1_act" joint="wrist_1_joint" kp="100" ctrlrange="-3.14159265 3.14159265" ctrllimited="true"/>
	<position name="wrist_2_act" joint="wrist_2_joint" kp="10" ctrlrange="-3.14159265 3.14159265" ctrllimited="true"/>
	<position name="wrist_3_act" joint="wrist_3_joint" kp="10" ctrlrange="-3.14159265 3.14159265" ctrllimited="true"/>
<!-- 	<position name="left_finger_act" joint="gripper_base_left_finger_joint" kp="10" ctrlrange="-0.055 -0.0027" ctrllimited="true"/>
	<position name="right_finger_act" joint="gripper_base_right_finger_joint" kp="10" ctrlrange="0.0027 0.055" ctrllimited="true"/> -->

<!-- 	<velocity name="shoulder_pan_velocity" joint="shoulder_pan_joint" kv="10" ctrllimited="true"/>
	<velocity name="shoulder_lift_velocity" joint="shoulder_lift_joint" kv="10" ctrllimited="true"/>
	<velocity name="elbow_velocity" joint="elbow_joint" kv="10" ctrllimited="true"/>
	<velocity name="wrist_1_velocity" joint="wrist_1_joint" kv="10" ctrllimited="true"/>
	<velocity name="wrist_2_velocity" joint="wrist_2_joint" kv="10" ctrllimited="true"/>
	<velocity name="wrist_3_velocity" joint="wrist_3_joint" kv="10" ctrllimited="true"/>
	<velocity name="left_finger_velocity" joint="gripper_base_left_finger_joint" kv="10" ctrllimited="true"/>
	<velocity name="right_finger_velocity" joint="gripper_base_right_finger_joint" kv="10" ctrllimited="true"/> -->

  </actuator>
</mujoco>

